2024-05-27 09:08:39,049 INFO    StreamThr :198787 [internal.py:wandb_internal():86] W&B internal server running at pid: 198787, started at: 2024-05-27 09:08:39.048908
2024-05-27 09:08:39,051 DEBUG   HandlerThread:198787 [handler.py:handle_request():146] handle_request: status
2024-05-27 09:08:39,054 INFO    WriterThread:198787 [datastore.py:open_for_write():87] open: /home/ubuntu/21thanh.ht/imbalanced_dynamics/source/wandb/run-20240527_090839-wsqx002y/run-wsqx002y.wandb
2024-05-27 09:08:39,055 DEBUG   SenderThread:198787 [sender.py:send():379] send: header
2024-05-27 09:08:39,062 DEBUG   SenderThread:198787 [sender.py:send():379] send: run
2024-05-27 09:08:44,063 DEBUG   HandlerThread:198787 [handler.py:handle_request():146] handle_request: keepalive
2024-05-27 09:08:49,065 DEBUG   HandlerThread:198787 [handler.py:handle_request():146] handle_request: keepalive
2024-05-27 09:08:54,066 DEBUG   HandlerThread:198787 [handler.py:handle_request():146] handle_request: keepalive
2024-05-27 09:08:59,068 DEBUG   HandlerThread:198787 [handler.py:handle_request():146] handle_request: keepalive
2024-05-27 09:09:04,069 DEBUG   HandlerThread:198787 [handler.py:handle_request():146] handle_request: keepalive
2024-05-27 09:09:09,071 DEBUG   HandlerThread:198787 [handler.py:handle_request():146] handle_request: keepalive
2024-05-27 09:09:14,073 DEBUG   HandlerThread:198787 [handler.py:handle_request():146] handle_request: keepalive
2024-05-27 09:09:19,074 DEBUG   HandlerThread:198787 [handler.py:handle_request():146] handle_request: keepalive
2024-05-27 09:09:24,076 DEBUG   HandlerThread:198787 [handler.py:handle_request():146] handle_request: keepalive
2024-05-27 09:09:29,078 DEBUG   HandlerThread:198787 [handler.py:handle_request():146] handle_request: keepalive
2024-05-27 09:09:34,079 DEBUG   HandlerThread:198787 [handler.py:handle_request():146] handle_request: keepalive
2024-05-27 09:09:39,081 DEBUG   HandlerThread:198787 [handler.py:handle_request():146] handle_request: keepalive
2024-05-27 09:09:42,373 INFO    SenderThread:198787 [retry.py:__call__():172] Retry attempt failed:
Traceback (most recent call last):
  File "/home/ubuntu/miniconda3/envs/emthanhcv/lib/python3.10/site-packages/urllib3/connectionpool.py", line 467, in _make_request
    self._validate_conn(conn)
  File "/home/ubuntu/miniconda3/envs/emthanhcv/lib/python3.10/site-packages/urllib3/connectionpool.py", line 1099, in _validate_conn
    conn.connect()
  File "/home/ubuntu/miniconda3/envs/emthanhcv/lib/python3.10/site-packages/urllib3/connection.py", line 653, in connect
    sock_and_verified = _ssl_wrap_socket_and_match_hostname(
  File "/home/ubuntu/miniconda3/envs/emthanhcv/lib/python3.10/site-packages/urllib3/connection.py", line 806, in _ssl_wrap_socket_and_match_hostname
    ssl_sock = ssl_wrap_socket(
  File "/home/ubuntu/miniconda3/envs/emthanhcv/lib/python3.10/site-packages/urllib3/util/ssl_.py", line 465, in ssl_wrap_socket
    ssl_sock = _ssl_wrap_socket_impl(sock, context, tls_in_tls, server_hostname)
  File "/home/ubuntu/miniconda3/envs/emthanhcv/lib/python3.10/site-packages/urllib3/util/ssl_.py", line 509, in _ssl_wrap_socket_impl
    return ssl_context.wrap_socket(sock, server_hostname=server_hostname)
  File "/home/ubuntu/miniconda3/envs/emthanhcv/lib/python3.10/ssl.py", line 513, in wrap_socket
    return self.sslsocket_class._create(
  File "/home/ubuntu/miniconda3/envs/emthanhcv/lib/python3.10/ssl.py", line 1104, in _create
    self.do_handshake()
  File "/home/ubuntu/miniconda3/envs/emthanhcv/lib/python3.10/ssl.py", line 1375, in do_handshake
    self._sslobj.do_handshake()
TimeoutError: _ssl.c:990: The handshake operation timed out

The above exception was the direct cause of the following exception:

Traceback (most recent call last):
  File "/home/ubuntu/miniconda3/envs/emthanhcv/lib/python3.10/site-packages/requests/adapters.py", line 486, in send
    resp = conn.urlopen(
  File "/home/ubuntu/miniconda3/envs/emthanhcv/lib/python3.10/site-packages/urllib3/connectionpool.py", line 847, in urlopen
    retries = retries.increment(
  File "/home/ubuntu/miniconda3/envs/emthanhcv/lib/python3.10/site-packages/urllib3/util/retry.py", line 470, in increment
    raise reraise(type(error), error, _stacktrace)
  File "/home/ubuntu/miniconda3/envs/emthanhcv/lib/python3.10/site-packages/urllib3/util/util.py", line 39, in reraise
    raise value
  File "/home/ubuntu/miniconda3/envs/emthanhcv/lib/python3.10/site-packages/urllib3/connectionpool.py", line 793, in urlopen
    response = self._make_request(
  File "/home/ubuntu/miniconda3/envs/emthanhcv/lib/python3.10/site-packages/urllib3/connectionpool.py", line 491, in _make_request
    raise new_e
  File "/home/ubuntu/miniconda3/envs/emthanhcv/lib/python3.10/site-packages/urllib3/connectionpool.py", line 469, in _make_request
    self._raise_timeout(err=e, url=url, timeout_value=conn.timeout)
  File "/home/ubuntu/miniconda3/envs/emthanhcv/lib/python3.10/site-packages/urllib3/connectionpool.py", line 370, in _raise_timeout
    raise ReadTimeoutError(
urllib3.exceptions.ReadTimeoutError: HTTPSConnectionPool(host='api.wandb.ai', port=443): Read timed out. (read timeout=20)

During handling of the above exception, another exception occurred:

Traceback (most recent call last):
  File "/home/ubuntu/miniconda3/envs/emthanhcv/lib/python3.10/site-packages/wandb/sdk/lib/retry.py", line 131, in __call__
    result = self._call_fn(*args, **kwargs)
  File "/home/ubuntu/miniconda3/envs/emthanhcv/lib/python3.10/site-packages/wandb/sdk/internal/internal_api.py", line 369, in execute
    return self.client.execute(*args, **kwargs)  # type: ignore
  File "/home/ubuntu/miniconda3/envs/emthanhcv/lib/python3.10/site-packages/wandb/vendor/gql-0.2.0/wandb_gql/client.py", line 52, in execute
    result = self._get_result(document, *args, **kwargs)
  File "/home/ubuntu/miniconda3/envs/emthanhcv/lib/python3.10/site-packages/wandb/vendor/gql-0.2.0/wandb_gql/client.py", line 60, in _get_result
    return self.transport.execute(document, *args, **kwargs)
  File "/home/ubuntu/miniconda3/envs/emthanhcv/lib/python3.10/site-packages/wandb/sdk/lib/gql_request.py", line 58, in execute
    request = self.session.post(self.url, **post_args)
  File "/home/ubuntu/miniconda3/envs/emthanhcv/lib/python3.10/site-packages/requests/sessions.py", line 637, in post
    return self.request("POST", url, data=data, json=json, **kwargs)
  File "/home/ubuntu/miniconda3/envs/emthanhcv/lib/python3.10/site-packages/requests/sessions.py", line 589, in request
    resp = self.send(prep, **send_kwargs)
  File "/home/ubuntu/miniconda3/envs/emthanhcv/lib/python3.10/site-packages/requests/sessions.py", line 703, in send
    r = adapter.send(request, **kwargs)
  File "/home/ubuntu/miniconda3/envs/emthanhcv/lib/python3.10/site-packages/requests/adapters.py", line 532, in send
    raise ReadTimeout(e, request=request)
requests.exceptions.ReadTimeout: HTTPSConnectionPool(host='api.wandb.ai', port=443): Read timed out. (read timeout=20)
2024-05-27 09:09:44,083 DEBUG   HandlerThread:198787 [handler.py:handle_request():146] handle_request: keepalive
2024-05-27 09:09:49,084 DEBUG   HandlerThread:198787 [handler.py:handle_request():146] handle_request: keepalive
2024-05-27 09:09:54,086 DEBUG   HandlerThread:198787 [handler.py:handle_request():146] handle_request: keepalive
2024-05-27 09:09:59,087 DEBUG   HandlerThread:198787 [handler.py:handle_request():146] handle_request: keepalive
2024-05-27 09:10:04,089 DEBUG   HandlerThread:198787 [handler.py:handle_request():146] handle_request: keepalive
2024-05-27 09:10:09,090 DEBUG   HandlerThread:198787 [handler.py:handle_request():146] handle_request: cancel
2024-05-27 09:10:09,091 DEBUG   HandlerThread:198787 [handler.py:handle_request():146] handle_request: cancel
2024-05-27 09:10:09,091 DEBUG   SenderThread:198787 [sender.py:send():388] Record cancelled: run
2024-05-27 09:10:09,092 DEBUG   HandlerThread:198787 [handler.py:handle_request():146] handle_request: status_report
2024-05-27 09:10:11,102 DEBUG   HandlerThread:198787 [handler.py:handle_request():146] handle_request: shutdown
2024-05-27 09:10:11,102 INFO    HandlerThread:198787 [handler.py:finish():866] shutting down handler
2024-05-27 09:10:12,092 INFO    SenderThread:198787 [sender.py:finish():1546] shutting down sender
2024-05-27 09:10:12,093 INFO    WriterThread:198787 [datastore.py:close():296] close: /home/ubuntu/21thanh.ht/imbalanced_dynamics/source/wandb/run-20240527_090839-wsqx002y/run-wsqx002y.wandb
