
Total number of parameters:  9231114




 20%|██████████████████████████████████▌                                                                                                                                          | 4/20 [01:31<06:02, 22.63s/it]Exception ignored in: <function _releaseLock at 0x7fcd635da840>
Traceback (most recent call last):
  File "/home/ubuntu/miniconda3/envs/EmThanhServer/lib/python3.11/logging/__init__.py", line 237, in _releaseLock
    def _releaseLock():
KeyboardInterrupt:
 20%|██████████████████████████████████▌                                                                                                                                          | 4/20 [01:57<07:49, 29.33s/it]
Traceback (most recent call last):
  File "/home/ubuntu/miniconda3/envs/EmThanhServer/lib/python3.11/site-packages/torch/utils/data/dataloader.py", line 1133, in _try_get_data
    data = self._data_queue.get(timeout=timeout)
           ^^^^^^^^^^^^^^^^^^^^^^^^^^^^^^^^^^^^^
  File "/home/ubuntu/miniconda3/envs/EmThanhServer/lib/python3.11/multiprocessing/queues.py", line 114, in get
    raise Empty
_queue.Empty
The above exception was the direct cause of the following exception:
Traceback (most recent call last):
  File "/home/ubuntu/21thanh.ht/imbalanced_dynamics/source/train_cifar10.py", line 162, in <module>
    for inputs_test, targets_test in test_dataloader:
  File "/home/ubuntu/miniconda3/envs/EmThanhServer/lib/python3.11/site-packages/torch/utils/data/dataloader.py", line 631, in __next__
    data = self._next_data()
           ^^^^^^^^^^^^^^^^^
  File "/home/ubuntu/miniconda3/envs/EmThanhServer/lib/python3.11/site-packages/torch/utils/data/dataloader.py", line 1329, in _next_data
    idx, data = self._get_data()
                ^^^^^^^^^^^^^^^^
  File "/home/ubuntu/miniconda3/envs/EmThanhServer/lib/python3.11/site-packages/torch/utils/data/dataloader.py", line 1295, in _get_data
    success, data = self._try_get_data()
                    ^^^^^^^^^^^^^^^^^^^^
  File "/home/ubuntu/miniconda3/envs/EmThanhServer/lib/python3.11/site-packages/torch/utils/data/dataloader.py", line 1146, in _try_get_data
    raise RuntimeError(f'DataLoader worker (pid(s) {pids_str}) exited unexpectedly') from e
RuntimeError: DataLoader worker (pid(s) 856829, 856830, 856831, 856833, 856834, 856835) exited unexpectedly