2024-05-27 07:39:39,297 INFO    StreamThr :182758 [internal.py:wandb_internal():86] W&B internal server running at pid: 182758, started at: 2024-05-27 07:39:39.297075
2024-05-27 07:39:39,300 DEBUG   HandlerThread:182758 [handler.py:handle_request():146] handle_request: status
2024-05-27 07:39:39,303 INFO    WriterThread:182758 [datastore.py:open_for_write():87] open: /home/ubuntu/21thanh.ht/imbalanced_dynamics/source/wandb/run-20240527_073939-ue8s2krv/run-ue8s2krv.wandb
2024-05-27 07:39:39,303 DEBUG   SenderThread:182758 [sender.py:send():379] send: header
2024-05-27 07:39:39,310 DEBUG   SenderThread:182758 [sender.py:send():379] send: run
2024-05-27 07:39:44,311 DEBUG   HandlerThread:182758 [handler.py:handle_request():146] handle_request: keepalive
2024-05-27 07:39:44,322 DEBUG   HandlerThread:182758 [handler.py:handle_request():146] handle_request: shutdown
2024-05-27 07:39:44,322 INFO    HandlerThread:182758 [handler.py:finish():866] shutting down handler
2024-05-27 07:39:45,311 INFO    WriterThread:182758 [datastore.py:close():296] close: /home/ubuntu/21thanh.ht/imbalanced_dynamics/source/wandb/run-20240527_073939-ue8s2krv/run-ue8s2krv.wandb
2024-05-27 07:40:42,967 INFO    SenderThread:182758 [retry.py:__call__():172] Retry attempt failed:
Traceback (most recent call last):
  File "/home/ubuntu/miniconda3/envs/emthanhcv/lib/python3.10/site-packages/urllib3/connectionpool.py", line 467, in _make_request
    self._validate_conn(conn)
  File "/home/ubuntu/miniconda3/envs/emthanhcv/lib/python3.10/site-packages/urllib3/connectionpool.py", line 1099, in _validate_conn
    conn.connect()
  File "/home/ubuntu/miniconda3/envs/emthanhcv/lib/python3.10/site-packages/urllib3/connection.py", line 653, in connect
    sock_and_verified = _ssl_wrap_socket_and_match_hostname(
  File "/home/ubuntu/miniconda3/envs/emthanhcv/lib/python3.10/site-packages/urllib3/connection.py", line 806, in _ssl_wrap_socket_and_match_hostname
    ssl_sock = ssl_wrap_socket(
  File "/home/ubuntu/miniconda3/envs/emthanhcv/lib/python3.10/site-packages/urllib3/util/ssl_.py", line 465, in ssl_wrap_socket
    ssl_sock = _ssl_wrap_socket_impl(sock, context, tls_in_tls, server_hostname)
  File "/home/ubuntu/miniconda3/envs/emthanhcv/lib/python3.10/site-packages/urllib3/util/ssl_.py", line 509, in _ssl_wrap_socket_impl
    return ssl_context.wrap_socket(sock, server_hostname=server_hostname)
  File "/home/ubuntu/miniconda3/envs/emthanhcv/lib/python3.10/ssl.py", line 513, in wrap_socket
    return self.sslsocket_class._create(
  File "/home/ubuntu/miniconda3/envs/emthanhcv/lib/python3.10/ssl.py", line 1104, in _create
    self.do_handshake()
  File "/home/ubuntu/miniconda3/envs/emthanhcv/lib/python3.10/ssl.py", line 1375, in do_handshake
    self._sslobj.do_handshake()
TimeoutError: _ssl.c:990: The handshake operation timed out

The above exception was the direct cause of the following exception:

Traceback (most recent call last):
  File "/home/ubuntu/miniconda3/envs/emthanhcv/lib/python3.10/site-packages/requests/adapters.py", line 486, in send
    resp = conn.urlopen(
  File "/home/ubuntu/miniconda3/envs/emthanhcv/lib/python3.10/site-packages/urllib3/connectionpool.py", line 847, in urlopen
    retries = retries.increment(
  File "/home/ubuntu/miniconda3/envs/emthanhcv/lib/python3.10/site-packages/urllib3/util/retry.py", line 470, in increment
    raise reraise(type(error), error, _stacktrace)
  File "/home/ubuntu/miniconda3/envs/emthanhcv/lib/python3.10/site-packages/urllib3/util/util.py", line 39, in reraise
    raise value
  File "/home/ubuntu/miniconda3/envs/emthanhcv/lib/python3.10/site-packages/urllib3/connectionpool.py", line 793, in urlopen
    response = self._make_request(
  File "/home/ubuntu/miniconda3/envs/emthanhcv/lib/python3.10/site-packages/urllib3/connectionpool.py", line 491, in _make_request
    raise new_e
  File "/home/ubuntu/miniconda3/envs/emthanhcv/lib/python3.10/site-packages/urllib3/connectionpool.py", line 469, in _make_request
    self._raise_timeout(err=e, url=url, timeout_value=conn.timeout)
  File "/home/ubuntu/miniconda3/envs/emthanhcv/lib/python3.10/site-packages/urllib3/connectionpool.py", line 370, in _raise_timeout
    raise ReadTimeoutError(
urllib3.exceptions.ReadTimeoutError: HTTPSConnectionPool(host='api.wandb.ai', port=443): Read timed out. (read timeout=20)

During handling of the above exception, another exception occurred:

Traceback (most recent call last):
  File "/home/ubuntu/miniconda3/envs/emthanhcv/lib/python3.10/site-packages/wandb/sdk/lib/retry.py", line 131, in __call__
    result = self._call_fn(*args, **kwargs)
  File "/home/ubuntu/miniconda3/envs/emthanhcv/lib/python3.10/site-packages/wandb/sdk/internal/internal_api.py", line 369, in execute
    return self.client.execute(*args, **kwargs)  # type: ignore
  File "/home/ubuntu/miniconda3/envs/emthanhcv/lib/python3.10/site-packages/wandb/vendor/gql-0.2.0/wandb_gql/client.py", line 52, in execute
    result = self._get_result(document, *args, **kwargs)
  File "/home/ubuntu/miniconda3/envs/emthanhcv/lib/python3.10/site-packages/wandb/vendor/gql-0.2.0/wandb_gql/client.py", line 60, in _get_result
    return self.transport.execute(document, *args, **kwargs)
  File "/home/ubuntu/miniconda3/envs/emthanhcv/lib/python3.10/site-packages/wandb/sdk/lib/gql_request.py", line 58, in execute
    request = self.session.post(self.url, **post_args)
  File "/home/ubuntu/miniconda3/envs/emthanhcv/lib/python3.10/site-packages/requests/sessions.py", line 637, in post
    return self.request("POST", url, data=data, json=json, **kwargs)
  File "/home/ubuntu/miniconda3/envs/emthanhcv/lib/python3.10/site-packages/requests/sessions.py", line 589, in request
    resp = self.send(prep, **send_kwargs)
  File "/home/ubuntu/miniconda3/envs/emthanhcv/lib/python3.10/site-packages/requests/sessions.py", line 703, in send
    r = adapter.send(request, **kwargs)
  File "/home/ubuntu/miniconda3/envs/emthanhcv/lib/python3.10/site-packages/requests/adapters.py", line 532, in send
    raise ReadTimeout(e, request=request)
requests.exceptions.ReadTimeout: HTTPSConnectionPool(host='api.wandb.ai', port=443): Read timed out. (read timeout=20)
2024-05-27 10:56:39,438 INFO    SenderThread:182758 [dir_watcher.py:__init__():211] watching files in: /home/ubuntu/21thanh.ht/imbalanced_dynamics/source/wandb/run-20240527_073939-ue8s2krv/files
2024-05-27 10:56:39,438 INFO    SenderThread:182758 [sender.py:_start_run_threads():1124] run started: ue8s2krv with start time 1716795579.297294
2024-05-27 10:56:39,438 INFO    SenderThread:182758 [sender.py:finish():1546] shutting down sender
2024-05-27 10:56:39,438 INFO    SenderThread:182758 [dir_watcher.py:finish():358] shutting down directory watcher
2024-05-27 10:56:40,438 INFO    SenderThread:182758 [dir_watcher.py:finish():388] scan: /home/ubuntu/21thanh.ht/imbalanced_dynamics/source/wandb/run-20240527_073939-ue8s2krv/files
2024-05-27 10:56:40,439 INFO    SenderThread:182758 [dir_watcher.py:finish():402] scan save: /home/ubuntu/21thanh.ht/imbalanced_dynamics/source/wandb/run-20240527_073939-ue8s2krv/files/config.yaml config.yaml
2024-05-27 10:56:40,439 INFO    SenderThread:182758 [file_pusher.py:finish():172] shutting down file pusher
2024-05-27 10:56:40,440 INFO    SenderThread:182758 [file_pusher.py:join():178] waiting for file pusher
2024-05-27 10:56:41,319 INFO    wandb-upload_0:182758 [upload_job.py:push():131] Uploaded file /home/ubuntu/21thanh.ht/imbalanced_dynamics/source/wandb/run-20240527_073939-ue8s2krv/files/config.yaml
2024-05-27 10:56:41,942 INFO    SenderThread:182758 [file_stream.py:finish():614] file stream finish called
2024-05-27 10:56:42,353 INFO    SenderThread:182758 [file_stream.py:finish():618] file stream finish is done
