2024-05-27 08:53:18,068 INFO    MainThread:192435 [wandb_setup.py:_flush():76] Current SDK version is 0.16.5
2024-05-27 08:53:18,068 INFO    MainThread:192435 [wandb_setup.py:_flush():76] Configure stats pid to 192435
2024-05-27 08:53:18,068 INFO    MainThread:192435 [wandb_setup.py:_flush():76] Loading settings from /home/ubuntu/.config/wandb/settings
2024-05-27 08:53:18,068 INFO    MainThread:192435 [wandb_setup.py:_flush():76] Loading settings from /home/ubuntu/21thanh.ht/imbalanced_dynamics/source/wandb/settings
2024-05-27 08:53:18,068 INFO    MainThread:192435 [wandb_setup.py:_flush():76] Loading settings from environment variables: {}
2024-05-27 08:53:18,068 INFO    MainThread:192435 [wandb_setup.py:_flush():76] Applying setup settings: {'_disable_service': False}
2024-05-27 08:53:18,068 INFO    MainThread:192435 [wandb_setup.py:_flush():76] Inferring run settings from compute environment: {'program_relpath': 'source/train_cifar10_noaccel.py', 'program_abspath': '/home/ubuntu/21thanh.ht/imbalanced_dynamics/source/train_cifar10_noaccel.py', 'program': '/home/ubuntu/21thanh.ht/imbalanced_dynamics/source/train_cifar10_noaccel.py'}
2024-05-27 08:53:18,068 INFO    MainThread:192435 [wandb_setup.py:_flush():76] Applying login settings: {}
2024-05-27 08:53:18,068 INFO    MainThread:192435 [wandb_init.py:_log_setup():527] Logging user logs to /home/ubuntu/21thanh.ht/imbalanced_dynamics/source/wandb/run-20240527_085318-zqdvv803/logs/debug.log
2024-05-27 08:53:18,069 INFO    MainThread:192435 [wandb_init.py:_log_setup():528] Logging internal logs to /home/ubuntu/21thanh.ht/imbalanced_dynamics/source/wandb/run-20240527_085318-zqdvv803/logs/debug-internal.log
2024-05-27 08:53:18,069 INFO    MainThread:192435 [wandb_init.py:init():567] calling init triggers
2024-05-27 08:53:18,069 INFO    MainThread:192435 [wandb_init.py:init():574] wandb.init called with sweep_config: {}
config: {'learning_rate': 0.1, 'architecture': 'VGG11', 'dataset': 'CIFAR-10', 'epochs': 20, 'deterministic': False, 'imb_degree': 1}
2024-05-27 08:53:18,069 INFO    MainThread:192435 [wandb_init.py:init():617] starting backend
2024-05-27 08:53:18,069 INFO    MainThread:192435 [wandb_init.py:init():621] setting up manager
2024-05-27 08:53:18,071 INFO    MainThread:192435 [backend.py:_multiprocessing_setup():105] multiprocessing start_methods=fork,spawn,forkserver, using: spawn
2024-05-27 08:53:18,073 INFO    MainThread:192435 [wandb_init.py:init():629] backend started and connected
2024-05-27 08:53:18,076 INFO    MainThread:192435 [wandb_init.py:init():721] updated telemetry
2024-05-27 08:53:18,084 INFO    MainThread:192435 [wandb_init.py:init():754] communicating run to backend with 90.0 second timeout
2024-05-27 08:54:16,448 INFO    Thread-1 (wrapped_target):192435 [retry.py:__call__():172] Retry attempt failed:
Traceback (most recent call last):
  File "/home/ubuntu/miniconda3/envs/emthanhcv/lib/python3.10/site-packages/urllib3/connectionpool.py", line 467, in _make_request
    self._validate_conn(conn)
  File "/home/ubuntu/miniconda3/envs/emthanhcv/lib/python3.10/site-packages/urllib3/connectionpool.py", line 1099, in _validate_conn
    conn.connect()
  File "/home/ubuntu/miniconda3/envs/emthanhcv/lib/python3.10/site-packages/urllib3/connection.py", line 653, in connect
    sock_and_verified = _ssl_wrap_socket_and_match_hostname(
  File "/home/ubuntu/miniconda3/envs/emthanhcv/lib/python3.10/site-packages/urllib3/connection.py", line 806, in _ssl_wrap_socket_and_match_hostname
    ssl_sock = ssl_wrap_socket(
  File "/home/ubuntu/miniconda3/envs/emthanhcv/lib/python3.10/site-packages/urllib3/util/ssl_.py", line 465, in ssl_wrap_socket
    ssl_sock = _ssl_wrap_socket_impl(sock, context, tls_in_tls, server_hostname)
  File "/home/ubuntu/miniconda3/envs/emthanhcv/lib/python3.10/site-packages/urllib3/util/ssl_.py", line 509, in _ssl_wrap_socket_impl
    return ssl_context.wrap_socket(sock, server_hostname=server_hostname)
  File "/home/ubuntu/miniconda3/envs/emthanhcv/lib/python3.10/ssl.py", line 513, in wrap_socket
    return self.sslsocket_class._create(
  File "/home/ubuntu/miniconda3/envs/emthanhcv/lib/python3.10/ssl.py", line 1104, in _create
    self.do_handshake()
  File "/home/ubuntu/miniconda3/envs/emthanhcv/lib/python3.10/ssl.py", line 1375, in do_handshake
    self._sslobj.do_handshake()
TimeoutError: _ssl.c:990: The handshake operation timed out

The above exception was the direct cause of the following exception:

Traceback (most recent call last):
  File "/home/ubuntu/miniconda3/envs/emthanhcv/lib/python3.10/site-packages/requests/adapters.py", line 486, in send
    resp = conn.urlopen(
  File "/home/ubuntu/miniconda3/envs/emthanhcv/lib/python3.10/site-packages/urllib3/connectionpool.py", line 847, in urlopen
    retries = retries.increment(
  File "/home/ubuntu/miniconda3/envs/emthanhcv/lib/python3.10/site-packages/urllib3/util/retry.py", line 470, in increment
    raise reraise(type(error), error, _stacktrace)
  File "/home/ubuntu/miniconda3/envs/emthanhcv/lib/python3.10/site-packages/urllib3/util/util.py", line 39, in reraise
    raise value
  File "/home/ubuntu/miniconda3/envs/emthanhcv/lib/python3.10/site-packages/urllib3/connectionpool.py", line 793, in urlopen
    response = self._make_request(
  File "/home/ubuntu/miniconda3/envs/emthanhcv/lib/python3.10/site-packages/urllib3/connectionpool.py", line 491, in _make_request
    raise new_e
  File "/home/ubuntu/miniconda3/envs/emthanhcv/lib/python3.10/site-packages/urllib3/connectionpool.py", line 469, in _make_request
    self._raise_timeout(err=e, url=url, timeout_value=conn.timeout)
  File "/home/ubuntu/miniconda3/envs/emthanhcv/lib/python3.10/site-packages/urllib3/connectionpool.py", line 370, in _raise_timeout
    raise ReadTimeoutError(
urllib3.exceptions.ReadTimeoutError: HTTPSConnectionPool(host='api.wandb.ai', port=443): Read timed out. (read timeout=20)

During handling of the above exception, another exception occurred:

Traceback (most recent call last):
  File "/home/ubuntu/miniconda3/envs/emthanhcv/lib/python3.10/site-packages/wandb/sdk/lib/retry.py", line 131, in __call__
    result = self._call_fn(*args, **kwargs)
  File "/home/ubuntu/miniconda3/envs/emthanhcv/lib/python3.10/site-packages/wandb/sdk/internal/internal_api.py", line 369, in execute
    return self.client.execute(*args, **kwargs)  # type: ignore
  File "/home/ubuntu/miniconda3/envs/emthanhcv/lib/python3.10/site-packages/wandb/vendor/gql-0.2.0/wandb_gql/client.py", line 52, in execute
    result = self._get_result(document, *args, **kwargs)
  File "/home/ubuntu/miniconda3/envs/emthanhcv/lib/python3.10/site-packages/wandb/vendor/gql-0.2.0/wandb_gql/client.py", line 60, in _get_result
    return self.transport.execute(document, *args, **kwargs)
  File "/home/ubuntu/miniconda3/envs/emthanhcv/lib/python3.10/site-packages/wandb/sdk/lib/gql_request.py", line 58, in execute
    request = self.session.post(self.url, **post_args)
  File "/home/ubuntu/miniconda3/envs/emthanhcv/lib/python3.10/site-packages/requests/sessions.py", line 637, in post
    return self.request("POST", url, data=data, json=json, **kwargs)
  File "/home/ubuntu/miniconda3/envs/emthanhcv/lib/python3.10/site-packages/requests/sessions.py", line 589, in request
    resp = self.send(prep, **send_kwargs)
  File "/home/ubuntu/miniconda3/envs/emthanhcv/lib/python3.10/site-packages/requests/sessions.py", line 703, in send
    r = adapter.send(request, **kwargs)
  File "/home/ubuntu/miniconda3/envs/emthanhcv/lib/python3.10/site-packages/requests/adapters.py", line 532, in send
    raise ReadTimeout(e, request=request)
requests.exceptions.ReadTimeout: HTTPSConnectionPool(host='api.wandb.ai', port=443): Read timed out. (read timeout=20)
2024-05-27 08:54:48,113 ERROR   MainThread:192435 [wandb_init.py:init():780] encountered error: Run initialization has timed out after 90.0 sec. 
Please refer to the documentation for additional information: https://docs.wandb.ai/guides/track/tracking-faq#initstarterror-error-communicating-with-wandb-process-
2024-05-27 08:54:50,121 ERROR   MainThread:192435 [wandb_init.py:init():1205] Run initialization has timed out after 90.0 sec. 
Please refer to the documentation for additional information: https://docs.wandb.ai/guides/track/tracking-faq#initstarterror-error-communicating-with-wandb-process-
Traceback (most recent call last):
  File "/home/ubuntu/miniconda3/envs/emthanhcv/lib/python3.10/site-packages/wandb/sdk/wandb_init.py", line 1187, in init
    run = wi.init()
  File "/home/ubuntu/miniconda3/envs/emthanhcv/lib/python3.10/site-packages/wandb/sdk/wandb_init.py", line 786, in init
    raise error
wandb.errors.CommError: Run initialization has timed out after 90.0 sec. 
Please refer to the documentation for additional information: https://docs.wandb.ai/guides/track/tracking-faq#initstarterror-error-communicating-with-wandb-process-
2024-05-27 08:54:53,119 WARNING MsgRouterThr:192435 [router.py:message_loop():77] message_loop has been closed
